Workbook

Sheet CAPA
A1: SUPERINTENDENCIA DO AEROPORTO DE VITORIA - SBVT
A2: GERENCIA DE MANUTENÇÃO - VTMN
A3: COORDENAÇÃO DE MANUTENÇÃO DE SISTEMAS OPERACIONAIS E SEGURANÇA - VTMN-2
A5: OBJETO: | B5: CONSTRUÇÃO DE CALÇADA CIDADÃ NA VIA DE ACESSO DA ÁREA SUL DO AEROPORTO EURICO DE AGUIAR SALLES - VITÓRIA/ES
A7: REGIONAL | B7: SÍTIO | C7: PREÇO BASE | D7: Nº ORÇAMENTO | F7: ESTIMATIVA DE CUSTO R$
A8: SRSE | B8: VT | C8: 41671 | D8: VT.01/202.91/40319.00 | F8: =PLANILHA!F60 -> 95964.675
A9: DOCUMENTOS DE REFERÊNCIA | D9: RESPONSÁVEL
A10: VT.01/202.01/40318.00 | D10: LUIS FERNANDO DIAS
A15: REVISÕES:
A16: Nº | B16: REVISÃO | E16: DATA | F16: RESPONSÁVEL
A21: OBSERVAÇÃO:
A24: ELABORADO POR: LUIS FERNANDO DIAS - CREA/RJ: 1985100024
A38: VALIDADO POR:
A43: VALIDADO POR:
A48: APROVADO POR:

Sheet PLANILHA
B1: MINISTÉRIO DA GESTÃO E DA INOVAÇÃO EM SERVIÇOS PÚBLICOS
B2: Superintendência Regional de Administração do Espírito Santo
B3: SRA/ES
E4: DATA | F4: REV.
E5: 45527 | F5: 1
A6: TÍTULO: | B6: REFORMAS E MELHORIAS NAS INSTALAÇÕES DA CENTRAL DE ÁGUA GELADA (CAG), INCLUÍNDO A CONSTRUÇÃO DE UM CARRINHO PARA MOVIMENTAÇÃO DOS EQUIPAMENTOS DA CAG E REFORMA DO GUINDASTE DA CAG NO PRÉDIO SEDE DO MINISTÉRIO DA GESTÃO E DA INOVAÇÃO NO ESTADO DO ESPÍRITO SANTO, SOBRE A GESTÃO DA SUPERINTENDÊNCIA REGIONAL DE ADMINISTRAÇÃO - SRA/ES.
A8: PLANILHA DE SERVIÇOS E OBRAS
A9: ITENS | B9: SERVIÇOS | C9: UNID. | D9: QUANT. | E9: P.UNIT. | F9: P.TOTAL
A11: 1 | B11: CARRINHO DE MOVIMENTAÇÃO DE CARGA
A13: 1.1 | B13: Fabricação e montagem de carrinho para movimentação de carga em Central de Água Gelada (CAG), estrutura metálica em vigas perfil "I" de 3" com soldas contínuas, piso em chapa xadrez de alumínio antiderrapante de 3mm, deslocamento sobre trilhos de barra redonda maciça de 3/4", roldanas de 2 1/2" com rolamentos duplos na parte inferior, dois freios com sistema de alavanca e trava, pintura protetora com alcatrão de hulha bicomponente, similar à marca Internacional, atendendo às especificações de projeto quanto à durabilidade, segurança e funcionalidade. | C13: un | D13: 1 | E13: 5458.5 | F13: =D13*E13 -> 5458.5
A15: 2 | B15: ESTURUTURA DE SUPORTE DO CARRINHO
A17: 2.1 | B17: Fornecimento e montagem de estrutura metálica para suporte de carrinho de movimentação de cargas em Central de Água Gelada (CAG), constituída por vigas perfil "I" de 3", com trilho em barra redonda maciça de 3/4" soldada sobre o perfil, incluindo travamento inferior e guias laterais em barra chata de aço carbono de 1" x 1/8" (25,4mm x 3,18mm), batentes em barra chata de aço carbono, e todos os elementos de fixação e conexão necessários. A estrutura receberá tratamento anticorrosivo com pintura de alcatrão de hulha bicomponente, similar à marca Internacional, para proteção contra intempéries. O serviço compreende o fornecimento de todos os materiais, mão de obra especializada, equipamentos necessários para fabricação, transporte e montagem no local, incluindo soldas contínuas, ajustes e alinhamentos para garantir a precisão do movimento do carrinho. A unidade de medida será em kg de aço efetivamente instalado, considerando o peso teórico de todos os perfis e componentes metálicos utilizados na fabricação da estrutura completa. | C17: kg | D17: 450 | E17: 17.47 | F17: =D17*E17 -> 7861.5
A19: 3 | B19: PASSARELA METÁLICA PARA CAG
A21: 3.1 | B21: Fornecimento e montagem de passarela metálica para acesso e manutenção na Central de Água Gelada (CAG), com prolongamento de 2 metros em relação à estrutura existente. A passarela será composta por vigas de perfil "I" de 3" em aço estrutural, revestida com chapa xadrez de alumínio de 3 mm de espessura, proporcionando uma superfície antiderrapante. O serviço inclui a instalação de guarda-corpos em tubos de aço galvanizado com altura mínima de 1,10 m, rodapés metálicos de 15 cm de altura e escada de acesso com 1,30 m de comprimento e degraus de 20 cm. Todo o conjunto receberá tratamento superficial e pintura com tinta alcatrão de hulha bicomponente, assegurando proteção contra corrosão e durabilidade, conforme especificações técnicas. | C21: m² | D21: 2 | E21: 1433.3 | F21: =D21*E21 -> 2866.6
A23: 4 | B23: GUINDASTE (GRUA) PARA CAG
A25: 4.1 | B25: GUINDASTE DE MANUTENÇÃO DA CAG (GRUA), FORNECIMENTO E INSTALAÇÃO. Prolongamento do trilho de compensação em 2,00 m, utilizando viga perfil "I" 100 mm em aço carbono, soldada à estrutura existente; substituição do cabo de aço existente por novo cabo de aço compatível; instalação de contrapeso em caixa de aço carbono com dimensões 500 x 600 x 400 mm (L x C x A), preenchida com concreto C20, peso aproximado de 280 kg, com movimentação livre; base quadrada em chapa de aço carbono 400 x 400 mm, espessura 5/8" (15,875 mm); tubo externo em aço carbono diâmetro maior que 8" para permitir folga entre os tubos de no máximo 1 cm; tubo interno superior em aço carbono diâmetro 8"; mecanismo para inserir graxa; orifício para lubrificação com niple de 1/2" com tampão de 1/2" soldado, com inclinação de 45 graus; flanges H=30 cm soldadas no tubo externo nas partes superior e inferior; flange solta entre as duas flanges fixas H=30 cm; altura total do conjunto 3,00 m. Inclui todos os elementos de fixação, solda e acabamento necessários, conforme projeto. | C25: un | D25: 1 | E25: 4269 | F25: =D25*E25 -> 4269
A27: 4.2 | B27: APLICAÇÃO DE FLANGE EM AÇO CARBONO, H=30MM, SOLDADO EM TUBO DE AÇO CARBONO DN 8" (203,2 MM). Fornecimento e instalação de flange em aço carbono, altura 30 mm, diâmetro compatível com tubo de 8", incluindo preparação da superfície, posicionamento, soldagem contínua em toda circunferência com eletrodo revestido, garantindo fixação e vedação adequadas, respeitando folga máxima de 1 cm entre tubos interno e externo. Inclui mão de obra especializada, materiais, equipamentos necessários e limpeza final. Execução conforme projeto e normas técnicas vigentes. | C27: un | D27: 3 | E27: 320.2 | F27: =D27*E27 -> 960.6
A29: 4.3 | B29: SUBSTITUIÇÃO DE TUBO GUIA INTERNO EM AÇO CARBONO DN 8" (203,2 MM) PARA GRUA DE MANUTENÇÃO. Fornecimento e instalação de tubo guia em aço carbono, diâmetro nominal 8" (203,2 mm), comprimento de 5,0 metros, incluindo corte, preparação das extremidades, tamponamento das extremidades superior e inferior, posicionamento, soldagem contínua da extremidade inferior à base fixa existente, garantindo fixação e estabilidade estrutural. Extremidade superior livre para movimentação da base superior da grua. Solda dimensionada para suportar cargas de trabalho previstas. Inclui remoção do tubo existente, mão de obra especializada, materiais, equipamentos necessários e limpeza final. Execução conforme projeto e normas técnicas vigentes. | C29: un | D29: 1 | E29: 2209 | F29: =D29*E29 -> 2209
A31: 4.4 | B31: INSTALAÇÃO DE ORIFÍCIO PARA LUBRIFICAÇÃO EM ESTRUTURA METÁLICA DE GRUA. Execução de furo com diâmetro de 1/2" (12,7 mm) e inclinação de 45 graus em tubo de aço carbono, incluindo fornecimento e instalação de niple de 1/2" com tampão. Posicionamento estratégico para fácil acesso e manutenção. Inclui preparação da superfície, execução do furo, rosqueamento, instalação do niple e tampão, teste de estanqueidade, limpeza e acabamento. Fornecimento de todos os materiais, mão de obra especializada e equipamentos necessários. Execução conforme projeto e normas técnicas vigentes. | C31: un | D31: 1 | E31: 61.5 | F31: =D31*E31 -> 61.5
A33: 5 | B33: VIGAS I DE REFORÇO E SUPORTES DE SUSTENTAÇÃO PARA COMPRESSOR, TANQUE DE LÍQUIDO E SERPENTINA DO CHILLER
A35: 5.1 | B35: EXECUÇÃO DE SUPORTE DE SUSTENTAÇÃO PARA COMPRESSOR E TANQUE DE LÍQUIDO. Fabricação e instalação de estrutura em viga de aço perfil "I" 4" x 2", com base em chapa de aço 3/8" (9,53 mm) dimensões 0,20 x 0,20 m, fixada à laje com 04 parafusos de ancoragem 1/2" por base. Inclui camada de neoprene e=10 mm entre estrutura e laje para amortecimento de vibrações. Fornecimento de materiais, corte, solda, furação, pintura anticorrosiva, fixação, nivelamento e acabamento. Execução conforme projeto e normas técnicas vigentes. Execução conforme ABNT NBR 8800 e ABNT NBR 14762. AF_01/2024. | C35: un | D35: 16 | E35: =Composição!F155 -> 649.6915 | F35: =D35*E35 -> 10395.064
A37: 5.2 | B37: EXECUÇÃO DE SUPORTE DE SUSTENTAÇÃO PARA SERPENTINA DO CHILLER. Fabricação e instalação de estrutura em viga de aço perfil "I" 4" x 2", com base em chapa de aço 3/8" (9,53 mm) dimensões 0,20 x 0,20 m, fixada à laje com 04 parafusos de ancoragem 1/2" por base. Inclui camada de neoprene e=10 mm entre estrutura e laje para amortecimento de vibrações. Fornecimento de materiais, corte, solda, furação, pintura anticorrosiva, fixação, nivelamento e acabamento. Execução conforme projeto e normas técnicas vigentes. Execução conforme ABNT NBR 8800 e ABNT NBR 14762. AF_01/2024. | C37: un | D37: 24 | E37: =Composição!F155 -> 649.6915 | F37: =D37*E37 -> 15592.596
A39: 5.3 | B39: FORNECIMENTO E MONTAGEM DE VIGAS I PARA REFORÇO NA SUSTENTAÇÃO DE SERPENTINAS DO CHILLER. Perfil de aço ASTM A36 tipo I W150 x 22,5 (6" x 4"), alma 152 mm, mesa 102 mm, espessura alma 5,8 mm, espessura mesa 9,1 mm, peso 22,5 kg/m. Comprimento total 40 m. Inclui corte, furação, soldas de fixação MIG/MAG, aplicação de primer epóxi (1 demão, 25 μm) e pintura esmalte sintético (2 demãos, 50 μm cada). Montagem com parafusos de alta resistência ASTM A325 5/8" x 2", porcas e arruelas. Capacidade de carga conforme projeto estrutural. Limpeza, remoção de rebarbas e acabamento final. Execução conforme ABNT NBR 8800 e projeto. AF_01/2024. | C39: kg | D39: 900 | E39: =Composição!F170 -> 20.4342 | F39: =D39*E39 -> 18390.78
A41: 6 | B41: CAIXA DE ISOLAMENTO DE CONDENSAÇÃO DO ROTOR DAS BOMBAS
A43: 6.1 | B43: FABRICAÇÃO E INSTALAÇÃO DE CAIXA DE ISOLAMENTO PARA BOMBAS DE 20 E 25CV. Caixa em chapa de alumínio e=2,5mm, dimensões 54x20x50cm, com acabamento liso. Preenchimento interno com espuma expansiva bicomponente (A+B). Fixação superior em formato redondo à estrutura existente. Base inferior moldada e fixada na bomba d'água. Abertura traseira para acesso e manutenção, mantendo parafusos do conjunto motobomba acessíveis. Inclui corte, dobra, soldagem, aplicação de espuma, fixações e acabamento. Fornecimento de materiais, mão de obra e equipamentos necessários. Execução conforme projeto e normas técnicas vigentes. | C43: un | D43: 6 | E43: 1284 | F43: =D43*E43 -> 7704
A45: 7 | B45: REMOÇÃO E REINSTALAÇÃO DO TELHADO METÁLICO
A47: 7.1 | B47: REMOÇÃO E REINSTALAÇÃO DE TELHADO METÁLICO COM REAPROVEITAMENTO. Desmontagem cuidadosa de telhas metálicas, estrutura de apoio e elementos de fixação. Armazenamento temporário, transporte vertical e horizontal dos componentes. Remontagem da estrutura e cobertura, utilizando material reaproveitado. Inclui mão de obra especializada, ferramentas, equipamentos de segurança, limpeza final e descarte adequado de resíduos. Execução conforme normas técnicas e de segurança vigentes. | C47: m² | D47: 20 | E47: 21.45 | F47: =D47*E47 -> 429
A49: 8 | B49: LIMPEZA GERAL E DESTINAÇÃO DOS RESÍDUOS
A51: 8.1 | B51: LIMPEZA GERAL DE OBRA COM REMOÇÃO DE ENTULHO, INCLUINDO TRANSPORTE E DESTINAÇÃO FINAL. Compreende varrição, coleta, ensacamento de resíduos e entulhos provenientes da obra, carregamento manual, transporte em caminhão basculante até aterro sanitário credenciado pela Prefeitura Municipal de Vitória (PMV), e pagamento de taxa de destinação final. Inclui fornecimento de mão de obra, materiais, equipamentos e ferramentas necessárias. Execução conforme normas ambientais e de segurança vigentes. AF_04/2019 | C51: m² | D51: 120 | E51: 4.78 | F51: =D51*E51 -> 573.6
B54: Subtotal | F54: =SUM(F13:F52) -> 76771.74
E57: SUBTOTAL | F57: =F54 -> 76771.74
E58: COM BDI 25% | F58: =F57*0.25 -> 19192.935
E60: TOTAL | F60: =F57+F58 -> 95964.675
A61: OBSERVAÇÕES GERAIS:
B63: a) Para dúvidas em relação ao especificado a Contratada deverá procurar o Engº. Luís Fernando, através do tel.: (27) 3211–5328;
B64: b) A contratada deverá apresentar à contratante cronograma de execução dos serviços adequado à disponibilidade de horários e que não comprometa as funcionalidades do prédio;
B65: c) Não será permitido a Contratada uma terceirização de serviços;
B66: d) Todos os serviços serão entregues no prazo máximo de 60 dias;
B67: e) A garantia dos serviços será de 5 anos;
B68: f) A Contratada deverá apresentar uma programação de execução da obra.
...

Sheet Composição
A1: Código | B1: Descrição | C1: Unidade | D1: Quantidade | E1: Preço Unitário (R$) | F1: Custo Total (R$)
A2: Carrinho de Movimentação de Carga: un
A3: SINAPI 43082 | B3: Viga metálica perfil "I" 3" | C3: kg | D3: 80 | E3: 10.91 | F3: =D3*E3 -> 872.8
A4: EMOP 050104 | B4: Chapa de alumínio xadrez e=3mm | C4: m² | D4: 2 | E4: 495 | F4: =D4*E4 -> 990
A5: Cotação | B5: Roldana 2 1/2" com rolamento duplo | C5: un | D5: 4 | E5: 85 | F5: =D5*E5 -> 340
A6: Cotação | B6: Sistema de freio com alavanca e trava | C6: cj | D6: 2 | E6: 250 | F6: =D6*E6 -> 500
A7: SINAPI 98510 | B7: Solda contínua | C7: m | D7: 20 | E7: 29.83 | F7: =D7*E7 -> 596.6
A8: SINAPI 100772 | B8: Pintura com alcatrão de hulha bicomponente | C8: m² | D8: 10 | E8: 52.41 | F8: =D8*E8 -> 524.1
A9: SINAPI 88315 | B9: Mão de obra de serralheiro | C9: h | D9: 40 | E9: 22.54 | F9: =D9*E9 -> 901.6
A10: SINAPI 88316 | B10: Mão de obra de ajudante de serralheiro | C10: h | D10: 40 | E10: 17.17 | F10: =D10*E10 -> 686.8
E11: TOTAL | F11: =SUM(F3:F10) -> 5411.9
A13: Estrutura de Suporte do Carrinho: Kg
A14: SINAPI 43082 | B14: Perfil de aço laminado I de 3" | C14: kg | D14: 320 | E14: 10.91 | F14: =D14*E14 -> 3491.2
A15: SINAPI 43148 | B15: Barra de aço redonda 3/4" | C15: kg | D15: 46 | E15: 9.93 | F15: =D15*E15 -> 456.78
A16: SINAPI 43059 | B16: Barra chata de aço 1" x 1/8" | C16: kg | D16: 30 | E16: 9.13 | F16: =D16*E16 -> 273.9
A17: SINAPI 95241 | B17: Solda elétrica com eletrodo revestido 3,25 mm | C17: kg | D17: 19 | E17: 37.92 | F17: =D17*E17 -> 720.48
A18: SINAPI 102494 | B18: Pintura com tinta betuminosa | C18: m² | D18: 60 | E18: 14.61 | F18: =D18*E18 -> 876.6
A19: SINAPI 88315 | B19: Serralheiro | C19: h | D19: 40 | E19: 22.54 | F19: =D19*E19 -> 901.6
A20: SINAPI 88316 | B20: Ajudante de serralheiro | C20: h | D20: 40 | E20: 17.17 | F20: =D20*E20 -> 686.8
A21: SINAPI 92133 | B21: Serra circular de bancada | C21: h prod | D21: 32 | E21: 1.3 | F21: =D21*E21 -> 41.6
A22: SINAPI 92136 | B22: Máquina de solda elétrica | C22: h prod | D22: 32 | E22: 5 | F22: =D22*E22 -> 160
E23: TOTAL | F23: =SUM(F14:F22) -> 7608.96
A25: Passarela Metálica: m²
A26: SINAPI 43082 | B26: Perfil de aço laminado I 3" | C26: kg | D26: 45 | E26: 10.91 | F26: =D26*E26 -> 490.95
A27: EMOP 050104 | B27: Chapa de alumínio xadrez e=3mm | C27: m² | D27: 1 | E27: 495 | F27: =D27*E27 -> 495
A28: SINAPI 43192 | B28: Tubo de aço galvanizado 1 1/4" (guarda-corpo) | C28: m | D28: 2.75 | E28: 45 | F28: =D28*E28 -> 123.75
A29: SINAPI 43057 | B29: Chapa de aço carbono e=3mm (rodapé) | C29: kg | D29: 3.6 | E29: 8.5 | F29: =D29*E29 -> 30.6
A30: SICRO 5211435 | B30: Primer epóxi | C30: l | D30: 0.2 | E30: 65 | F30: =D30*E30 -> 13
A31: SICRO 5211456 | B31: Tinta alcatrão de hulha | C31: l | D31: 0.4 | E31: 45 | F31: =D31*E31 -> 18
A32: SINAPI 88316 | B32: Soldador | C32: h | D32: 2 | E32: 25 | F32: =D32*E32 -> 50
A33: SINAPI 88250 | B33: Ajudante de soldador | C33: h | D33: 2 | E33: 18 | F33: =D33*E33 -> 36
A34: SINAPI 88278 | B34: Montador de estrutura metálica | C34: h | D34: 3 | E34: 27 | F34: =D34*E34 -> 81
A35: SINAPI 88251 | B35: Ajudante de montador | C35: h | D35: 3 | E35: 19 | F35: =D35*E35 -> 57
A36: SINAPI 88310 | B36: Pintor | C36: h | D36: 1 | E36: 22 | F36: =D36*E36 -> 22
A37: SINAPI 88316 | B37: Servente | C37: h | D37: 1 | E37: 16 | F37: =D37*E37 -> 16
E38: TOTAL | F38: =SUM(F26:F37) -> 1433.3
A39: Guindaste (Grua) de Manutenção da CAG: un
A40: SINAPI 43060 | B40: Viga perfil "I" 100 mm em aço carbono | C40: kg | D40: 60 | E40: 12.5 | F40: =D40*E40 -> 750
A41: SINAPI 42732 | B41: Cabo de aço compatível | C41: m | D41: 10 | E41: 35 | F41: =D41*E41 -> 350
A42: SINAPI 43059 | B42: Chapa de aço carbono e=5/8" (15,875 mm) | C42: kg | D42: 20 | E42: 9.5 | F42: =D42*E42 -> 190
...

Sheet I-1
A9: COMPOSIÇÃO ANALÍTICA DE PREÇOS
A10: TÍTULO: | G10: Data Base
A11: =PLANILHA!#REF! -> #REF! | G11: =CAPA!C8 -> 41671
A15: Órgão: Infraero - Empresa Brasileira de Infraestrutura Aeroportuária
A16: Local: Aeroporto de Vitória - SBVT | G16: SINAPI - FEV 2014
A17: GERÊNCIA DE MANUTENÇÃO - VTMN
A18: CÓDIGO: I-1 | B18: Serviço: MOBILIZAÇÃO DE PESSOAL, MÁQUINAS E EQUIPAMENTOS | H18: Unidade un
A19: EQUIPAMENTO | B19: Unid. | C19: QUANT | D19: UTILIZAÇÃO | F19: CUSTO OPERACIONAL | H19: CUSTO HORÁRIO
D20: PROD | E20: IMPROD | F20: PROD | G20: IMPROD
A22: 41546 Mobilização e desmobilização de caminhão basculante (máximo)
B24: H | C24: 1 | D24: 177.56 | H24: =C24*D24 -> 177.56
A26: 41544 Mobilização e desmobilização de equipamentos com carreta prancha (máximo)
B29: H | C29: 1 | D29: 287.98 | H29: =C29*D29 -> 287.98
G31: (A) TOTAL | H31: =SUM(H21:H30) -> 465.54
A32: MÃO DE OBRA | D32: SINAPI | E32: UNID | F32: QUANTIDADE | G32: SALÁRIO BASE | H32: CUSTO HORÁRIO
E33: PROD | F33: IMPROD
A34: ENGENHEIRO CHEFE/SENIOR DE OBRA | D34: 2708 | E34: H | F34: 2 | G34: 75.26 | H34: =F34*G34 -> 150.52
A35: ENCARREGADO GERAL | D35: 4083 | E35: H | F35: 4 | G35: 7.35 | H35: =F35*G35 -> 29.4
A36: TÉCNICO DE EDIFICAÇÕES | D36: 2436 | E36: H | F36: 2 | G36: 10.81 | H36: =F36*G36 -> 21.62
A37: MOTORISTA DE VEÍCULO LEVE | D37: 4095 | E37: H | F37: 4 | G37: 4.89 | H37: =F37*G37 -> 19.56
G42: (B1) TOTAL | H42: =SUM(H34:H41) -> 221.1
A43: (B2)ENCARGOS SOCIAIS | D43: =Enc_Sociais!C43 -> 1.1066036 | H43: =ROUND(H42*D43,2) -> 244.67
E44: (B) TOTAL MDO (B1+B2) | H44: =+H42+H43 -> 465.77
A45: MATERIAIS | E45: UNID | F45: QUANTIDADE | G45: CUSTO UNITÁRIO | H45: CUSTO TOTAL
E46: PROD | F46: IMPROD
G49: (C) TOTAL | H49: =SUM(H47:H48) -> 0
A50: TRANSPORTE | D50: DTM | E50: UNIDADE | F50: QUANT. | G50: CUSTO UNITÁRIO | H50: CUSTO TOTAL
E51: PROD | F51: IMPROD
A53: Transporte local c/ carroceria 15 t rodov. pav. | D53: 30 | E53: tkm | F53: =30*10 -> 300 | G53: 0.58 | H53: =F53*G53 -> 174
A54: 1 A 00 002 40
G56: (D)TOTAL | H56: =SUM(H52:H55) -> 174
A57: PREÇO UNITÁRIO TOTAL (A) + (B) + (C) + (D) | G57: R$ | H57: =+H31+H44+H49+H56 -> 1105.31
A58: BONIFICAÇÃO | D58: 0.2623 | G58: R$ | H58: =ROUND(H57*D58,2) -> 289.92
A59: CUSTO UNITÁRIO TOTAL | G59: R$ | H59: =+H57+H58 -> 1395.23
A60: Engenheiro Civil - LUÍS FERNANDO DIAS - Responsável Técnico - CREA-RJ 1985100024
A61: Observações: O preço unitário total, inclui todos os custos diretos e indiretos. Os custos dos equipamentos são referência SINAPI-ES, Fevereiro/2014.

Sheet I-2
A9: COMPOSIÇÃO ANALÍTICA DE PREÇOS
A10: TÍTULO: | G10: Data Base
A11: RECUPERAÇÃO DE PAVIMENTO ASFÁLTICO DA FAIXA DE ROLAGEM DE AERONAVES ENTRE AS TAXIWAYS ALFA E BRAVA DO AEROPORTO EURICO DE AGUIAR SALLES - SBVT | G11: ='I-1'!G11:H11 -> 41671
A15: Órgão: Infraero - Empresa Brasileira de Infraestrutura Aeroportuária
A16: Local: Aeroporto de Vitória - SBVT | G16: ='I-1'!G16:H16 -> SINAPI - FEV 2014
A17: GERÊNCIA DE MANUTENÇÃO - VTMN
A18: CÓDIGO: I-2 | B18: Serviço:DESMOBILIZAÇÃO DE MÁQUINAS, PESSOAL E EQUIPAMENTOS | H18: Unidade un
A19: EQUIPAMENTO | B19: Unid. | C19: QUANT | D19: UTILIZAÇÃO | F19: CUSTO OPERACIONAL | H19: CUSTO HORÁRIO
D20: PROD | E20: IMPROD | F20: PROD | G20: IMPROD
A22: 41546 Mobilização e desmobilização de caminhão basculante (máximo)
B24: H | C24: 1 | D24: 177.56 | H24: =C24*D24 -> 177.56
A25: 41544 Mobilização e desmobilização de equipamentos com carreta prancha (máximo)
B28: H | C28: 1 | D28: 287.98 | H28: =C28*D28 -> 287.98
G30: (A) TOTAL | H30: =SUM(H21:H29) -> 465.54
A31: MÃO DE OBRA | E31: UNID | F31: QUANTIDADE | G31: SALÁRIO BASE | H31: CUSTO HORÁRIO
E32: PROD | F32: IMPROD
A33: ENGENHEIRO CHEFE/SENIOR DE OBRA | D33: 2708 | E33: H | F33: 2 | G33: 75.26 | H33: =F33*G33 -> 150.52
A34: ENCARREGADO GERAL | D34: 4083 | E34: H | F34: 4 | G34: 7.35 | H34: =F34*G34 -> 29.4
A35: TÉCNICO DE EDIFICAÇÕES | D35: 2436 | E35: H | F35: 2 | G35: 10.81 | H35: =F35*G35 -> 21.62
A36: MOTORISTA DE VEÍCULO LEVE | D36: 4095 | E36: H | F36: 4 | G36: 4.89 | H36: =F36*G36 -> 19.56
G42: (B1) TOTAL | H42: =SUM(H33:H41) -> 221.1
A43: (B2)ENCARGOS SOCIAIS | D43: =Enc_Sociais!C43 -> 1.1066036 | H43: =ROUND(H42*D43,2) -> 244.67
E44: (B) TOTAL MDO (B1+B2) | H44: =+H42+H43 -> 465.77
A45: MATERIAIS | E45: UNID | F45: QUANTIDADE | G45: CUSTO UNITÁRIO | H45: CUSTO TOTAL
E46: PROD | F46: IMPROD
G49: (C) TOTAL | H49: =SUM(H47:H48) -> 0
A50: TRANSPORTE | D50: DTM | E50: UNIDADE | F50: QUANT. | G50: CUSTO UNITÁRIO | H50: CUSTO TOTAL
E51: PROD | F51: IMPROD
A53: Transporte local c/ carroceria 15 t rodov. pav. | D53: 30 | E53: tkm | F53: =30*10 -> 300 | G53: 0.58 | H53: =F53*G53 -> 174
A54: 1 A 00 002 40
G56: (D)TOTAL | H56: =SUM(H52:H55) -> 174
A57: PREÇO UNITÁRIO TOTAL (A) + (B) + (C) + (D) | G57: R$ | H57: =+H30+H44+H49+H56 -> 1105.31
A58: BONIFICAÇÃO | D58: 0.2623 | G58: R$ | H58: =ROUND(H57*D58,2) -> 289.92
A59: CUSTO UNITÁRIO TOTAL | G59: R$ | H59: =+H57+H58 -> 1395.23
A60: Engenheiro Civil - LUÍS FERNANDO DIAS - Responsável Técnico - CREA-RJ 1985100024
A61: Observações: O preço unitário total, inclui todos os custos diretos e indiretos. Os custos dos equipamentos são referência SINAPI-ES, Fevereiro/2014.

Sheet 1.1
A9: COMPOSIÇÃO ANALÍTICA DE PREÇOS
A10: TÍTULO: | G10: ='I-1'!G10:H10 -> Data Base
A11: =PLANILHA!#REF! -> #REF! | G11: ='I-1'!G11:H11 -> 41671
A13: Órgão: Infraero - Empresa Brasileira de Infraestrutura Aeroportuária
A14: Local: Aeroporto de Vitória - SBVT | G14: ='I-1'!G16:H16 -> SINAPI - FEV 2014
A15: GERÊNCIA DE MANUTENÇÃO - VTMN
A16: CÓDIGO: Item 1.1 | B16: =PLANILHA!#REF! -> #REF! | H16: Unidade: un x mês
A17: EQUIPAMENTO | B17: Unid. | C17: QUANT | D17: UTILIZAÇÃO | F17: CUSTO OPERACIONAL | H17: CUSTO HORÁRIO
D18: PROD | E18: IMPROD | F18: PROD | G18: IMPROD
G23: (A) TOTAL | H23: =SUM(H19:H22) -> 0
A24: MÃO DE OBRA | D24: SINAPI | E24: UNID | F24: QUANTIDADE | G24: SALÁRIO BASE | H24: CUSTO HORÁRIO
E25: PROD | F25: IMPROD
G34: (B1) TOTAL | H34: =SUM(H26:H33) -> 0
A35: (B2)ENCARGOS SOCIAIS | D35: =Enc_Sociais!C43 -> 1.1066036 | H35: =ROUND(H34*D35,2) -> 0
E36: (B) TOTAL MDO (B1+B2) | H36: =+H34+H35 -> 0
A37: MATERIAIS | D37: sinapi | E37: UNID | F37: QUANTIDADE | G37: CUSTO UNITÁRIO | H37: CUSTO TOTAL
E38: PROD | F38: IMPROD
A39: Aluguel de container para almoxarifado | D39: 10776 | E39: un x mês | F39: 1 | G39: 662.5 | H39: =F39*G39 -> 662.5
G41: (C) TOTAL | H41: =SUM(H39:H40) -> 662.5
A42: TRANSPORTE | D42: DTM | E42: UNIDADE | F42: QUANT. | G42: CUSTO UNITÁRIO | H42: CUSTO TOTAL
E43: PROD | F43: IMPROD
G48: (D)TOTAL | H48: =SUM(H44:H47) -> 0
A49: PREÇO UNITÁRIO TOTAL (A) + (B) + (C) + (D) | G49: R$ | H49: =+H23+H36+H41+H48 -> 662.5
A50: BONIFICAÇÃO | D50: 0.2623 | G50: R$ | H50: =ROUND(H49*D50,2) -> 173.77
A51: CUSTO UNITÁRIO TOTAL | G51: R$ | H51: =+H49+H50 -> 836.27
A52: Engenheiro Civil - LUÍS FERNANDO DIAS - Responsável Técnico - CREA-RJ 1985100024
A53: Observações: O preço unitário total, inclui todos os custos diretos e indiretos

Sheet 1.2
A9: COMPOSIÇÃO ANALÍTICA DE PREÇOS
A10: TÍTULO: | G10: ='I-1'!G10:H10 -> Data Base
A11: =PLANILHA!#REF! -> #REF! | G11: ='I-1'!G11:H11 -> 41671
A13: Órgão: Infraero - Empresa Brasileira de Infraestrutura Aeroportuária
A14: Local: Aeroporto de Vitória - SBVT | G14: ='I-1'!G16:H16 -> SINAPI - FEV 2014
A15: GERÊNCIA DE MANUTENÇÃO - VTMN
A16: CÓDIGO: Item 1.2 | B16: =PLANILHA!#REF! -> #REF! | H16: Unidade unXmes
A17: EQUIPAMENTO | B17: Unid. | C17: QUANT | D17: UTILIZAÇÃO | F17: CUSTO OPERACIONAL | H17: CUSTO HORÁRIO
D18: PROD | E18: IMPROD | F18: PROD | G18: IMPROD
G23: (A) TOTAL | H23: =SUM(H19:H22) -> 0
A24: MÃO DE OBRA | E24: UNID | F24: QUANTIDADE | G24: SALÁRIO BASE | H24: CUSTO HORÁRIO
E25: PROD | F25: IMPROD
G31: (B1) TOTAL | H31: =SUM(H26:H30) -> 0
A32: (B2)ENCARGOS SOCIAIS | D32: =Enc_Sociais!C43 -> 1.1066036 | H32: =ROUND(H31*D32,2) -> 0
E33: (B) TOTAL MDO (B1+B2) | H33: =+H31+H32 -> 0
A34: MATERIAIS | D34: sinapi | E34: UNID | F34: QUANTIDADE | G34: CUSTO UNITÁRIO | H34: CUSTO TOTAL
E35: PROD | F35: IMPROD
A37: CONTAINER 2,30 X 4,30 M PARA SANITARIO COM 3 BACIAS, 4 CHUVEIROS, 1 LAVATÓRIO E 1 MICTÓRIO | D37: 10777 | E37: Mês | F37: 1 | G37: 972.5 | H37: =F37*G37 -> 972.5
G44: (C) TOTAL | H44: =SUM(H36:H43) -> 972.5
A45: TRANSPORTE | D45: DTM | E45: UNIDADE | F45: QUANT. | G45: CUSTO UNITÁRIO | H45: CUSTO TOTAL
E46: PROD | F46: IMPROD
G51: (D)TOTAL | H51: =SUM(H47:H50) -> 0
A52: PREÇO UNITÁRIO TOTAL (A) + (B) + (C) + (D) | G52: R$ | H52: =+H23+H33+H44+H51 -> 972.5
A53: BONIFICAÇÃO | D53: 0.2623 | G53: R$ | H53: =ROUND(H52*D53,2) -> 255.09
A54: CUSTO UNITÁRIO TOTAL | G54: R$ | H54: =+H52+H53 -> 1227.59
A55: Engenheiro Civil - LUÍS FERNANDO DIAS - Responsável Técnico - CREA-RJ 1985100024
A56: Observações: O preço unitário total, inclui todos os custos diretos e indiretos

Sheet 1.3
A9: COMPOSIÇÃO ANALÍTICA DE PREÇOS
A10: TÍTULO: | G10: ='I-1'!G10:H10 -> Data Base
A11: =PLANILHA!#REF! -> #REF! | G11: ='I-1'!G11:H11 -> 41671
A13: Órgão: Infraero - Empresa Brasileira de Infraestrutura Aeroportuária
A14: Local: Aeroporto de Vitória - SBVT | G14: ='I-1'!G16:H16 -> SINAPI - FEV 2014
A15: GERÊNCIA DE MANUTENÇÃO - VTMN
A16: CÓDIGO: Item 1.3 | B16: =PLANILHA!#REF! -> #REF! | H16: Unidade un
A17: EQUIPAMENTO | B17: Unid. | C17: QUANT | D17: UTILIZAÇÃO | F17: CUSTO OPERACIONAL | H17: CUSTO HORÁRIO
D18: PROD | E18: IMPROD | F18: PROD | G18: IMPROD
G23: (A) TOTAL | H23: =SUM(H19:H22) -> 0
A24: MÃO DE OBRA | D24: sinapi | E24: UNID | F24: QUANTIDADE | G24: SALÁRIO BASE | H24: CUSTO HORÁRIO
E25: PROD | F25: IMPROD
A26: 4750 PEDREIRO | D26: 4750 | E26: h | F26: 4 | G26: 5.51 | H26: =F26*G26 -> 22.04
A27: 1213 CARPINTEIRO DE FORMAS | D27: 1213 | E27: h | F27: 1 | G27: 5.51 | H27: =F27*G27 -> 5.51
A28: 2696 ENCANADOR OU BOMBEIRO HIDRAULICO | D28: 2696 | E28: h | F28: 4 | G28: 4.69 | H28: =F28*G28 -> 18.76
A29: 6111 SERVENTE | D29: 6111 | E29: h | F29: 4 | G29: 3.44 | H29: =F29*G29 -> 13.76
G35: (B1) TOTAL | H35: =SUM(H26:H34) -> 60.07
A36: (B2)ENCARGOS SOCIAIS | D36: 1.1066036 | H36: =ROUND(H35*D36,2) -> 66.47
E37: (B) TOTAL MDO (B1+B2) | H37: =+H35+H36 -> 126.54
A38: MATERIAIS | E38: UNID | F38: QUANTIDADE | G38: CUSTO UNITÁRIO | H38: CUSTO TOTAL
E39: PROD | F39: IMPROD
A40: 9868 TUBO PVC SOLDAVEL EB-892 P/AGUA FRIA PREDIAL DN 25MM
E41: m | F41: 12 | G41: 2.71 | H41: =F41*G41 -> 32.52
A42: 1357 CHAPA MADEIRA COMPENSADA RESINADA 2,2 X 1,1M (12MM) P/ FORMA CONCRETO
E43: m² | F43: 1 | G43: 43.27 | H43: =F43*G43 -> 43.27
A44: 4448 PEÇA DE MADEIRA 3A./4A QUALIDADE 7,5 X 12,50 CM (3X5") NÃO APARELHADA
E45: m | F45: 1 | G45: 13.22 | H45: =F45*G45 -> 13.22
A46: 5066 PREGO DE ACO 12 X 12 | E46: kg | F46: 0.5 | G46: 9.86 | H46: =F46*G46 -> 4.93
A47: 5075 PREGO DE ACO 18 X 30 | E47: kg | F47: 0.5 | G47: 7.35 | H47: =F47*G47 -> 3.675
A48: 7266 TIJOLO CERAMICO FURADO 10 X 20 X 20CM | E48: un | F48: 30 | G48: 0.55 | H48: =F48*G48 -> 16.5
A49: 6016 REGISTRO GAVETA 3/4" BRUTO LATAO REF 1502-B
E50: un | F50: 1 | G50: 18.87 | H50: =F50*G50 -> 18.87
A51: 11868 CAIXA D'AGUA FIBRA DE VIDRO 1000L | E51: un | F51: 1 | G51: 311.39 | H51: =F51*G51 -> 311.39
A52: 9836 TUBO PVC SERIE NORMAL - ESGOTO PREDIAL DN 100MM - NBR 5688
E53: m | F53: 1 | G53: 9.65 | H53: =F53*G53 -> 9.65
A54: 1965 CURVA PVC LONGA 45G P/ ESG PREDIAL DN 100MM
E55: un | F55: 1 | G55: 23.4 | H55: =F55*G55 -> 23.4
A56: 4884 ARGAMASSA DE CIMENTO E AREIA MEDIA NÃO PENEIRADA, NO TRACO 1:3 PREPARO MANUAL.
E57: m³ | F57: 1 | G57: 370.75 | H57: =F57*G57 -> 370.75
G59: (C) TOTAL | H59: =SUM(H40:H58) -> 848.175
...

Sheet 1.4
A9: COMPOSIÇÃO ANALÍTICA DE PREÇOS
A10: TÍTULO: | G10: ='I-1'!G10:H10 -> Data Base
A11: =PLANILHA!#REF! -> #REF! | G11: ='I-1'!G11:H11 -> 41671
A13: Órgão: Infraero - Empresa Brasileira de Infraestrutura Aeroportuária
A14: Local: Aeroporto de Vitória - SBVT | G14: ='I-1'!G16:H16 -> SINAPI - FEV 2014
A15: GERÊNCIA DE MANUTENÇÃO - VTMN
A16: CÓDIGO: Item 1.4 | B16: =PLANILHA!#REF! -> #REF! | H16: Unidade un
A17: EQUIPAMENTO | B17: Unid. | C17: QUANT | D17: UTILIZAÇÃO | F17: CUSTO OPERACIONAL | H17: CUSTO HORÁRIO
D18: PROD | E18: IMPROD | F18: PROD | G18: IMPROD
G23: (A) TOTAL | H23: =SUM(H19:H22) -> 0
A24: MÃO DE OBRA | E24: UNID | F24: QUANTIDADE | G24: SALÁRIO BASE | H24: CUSTO HORÁRIO
E25: PROD | F25: IMPROD
A27: 2436 ELETRICISTA OU OFICIAL ELETRICISTA | E27: h | F27: 16 | G27: 5.51 | H27: =F27*G27 -> 88.16
A28: 6111 AJUDANTE DE ELETRICISTA | E28: h | F28: 16 | G28: 3.44 | H28: =F28*G28 -> 55.04
G35: (B1) TOTAL | H35: =SUM(H26:H34) -> 143.2
A36: (B2)ENCARGOS SOCIAIS | D36: 1.1066036 | H36: =ROUND(H35*D36,2) -> 158.47
E37: (B) TOTAL MDO (B1+B2) | H37: =+H35+H36 -> 301.67
A38: MATERIAIS | E38: UNID | F38: QUANTIDADE | G38: CUSTO UNITÁRIO | H38: CUSTO TOTAL
E39: PROD | F39: IMPROD
A40: 2682 ELETRODUTO DE PVC ROSCÁVEL DE 2 1/2" (63 MM), SEM LUVA
E41: m | F41: 2 | G41: 17.41 | H41: =F41*G41 -> 34.82
A42: 2373 DISJUNTOR TERMOMAGNETICO TRIPOLAR 100A | E42: un | F42: 1 | G42: 67.73 | H42: =F42*G42 -> 67.73
A43: 862 CABO DE COBRE NU 10MM² MEIO DURO
E44: m | F44: 20 | G44: 4.29 | H44: =F44*G44 -> 85.8
A45: 2673 ELETRODUTO DE PVC ROSCÁVEL DE 1/2" (12,7 MM), SEM LUVA
E46: m | F46: 12 | G46: 1.73 | H46: =F46*G46 -> 20.76
A47: 1875 CURVA PVC 90G P/ ELETRODUTO ROSCAVEL 1 1/2" | E47: un | F47: 2 | G47: 5.53 | H47: =F47*G47 -> 11.06
A49: 20009 DISJUNTOR MONOFASICO 15A, 2KA (220V) | E49: un | F49: 1 | G49: 10.47 | H49: =F49*G49 -> 10.47
A50: 12056 ELETRODUTO METALICO FLEXIVEL TIPO CONDUITE D = 1 1/2"
E51: m | F51: 1 | G51: 22.06 | H51: =F51*G51 -> 22.06
A52: 20207 PECA DE MADEIRA (MASSARANDUBA) APARELHADA 1 1/2 X 3" (4 X 7, 5CM)
E53: m | F53: 6 | G53: 11.42 | H53: =F53*G53 -> 68.52
A54: 444 PINO RETO P/ ISOLADOR 15KV DIMENSOES 16 X 19 X 290MM
E55: un | F55: 4 | G55: 10.83 | H55: =F55*G55 -> 43.32
A56: 3406 ISOLADOR DE PORCELANA, TIPO PINO, DE 15 KV | E56: un | F56: 4 | G56: 12.35 | H56: =F56*G56 -> 49.4
A57: 0392 ABRACADEIRA TIPO D 1/2" C/ PARAFUSO" | E57: un | F57: 1 | G57: 0.47 | H57: =F57*G57 -> 0.47
G60: (C) TOTAL | H60: =SUM(H40:H59) -> 414.41
A61: TRANSPORTE | D61: DTM | E61: UNIDADE | F61: QUANT. | G61: CUSTO UNITÁRIO | H61: CUSTO TOTAL
E62: PROD | F62: IMPROD
G67: (D)TOTAL | H67: =SUM(H63:H66) -> 0
...

Sheet 1.5
A9: COMPOSIÇÃO ANALÍTICA DE PREÇOS
A10: TÍTULO: | G10: ='I-1'!G10:H10 -> Data Base
A11: =PLANILHA!#REF! -> #REF! | G11: ='I-1'!G11:H11 -> 41671
A13: Órgão: Infraero - Empresa Brasileira de Infraestrutura Aeroportuária
A14: Local: Aeroporto de Vitória - SBVT | G14: ='I-1'!G16:H16 -> SINAPI - FEV 2014
A15: GERÊNCIA DE MANUTENÇÃO - VTMN
A16: CÓDIGO: Item 1.5 | B16: =PLANILHA!#REF! -> #REF! | H16: Unidade m²
A17: EQUIPAMENTO | B17: Unid. | C17: QUANT | D17: UTILIZAÇÃO | F17: CUSTO OPERACIONAL | H17: CUSTO HORÁRIO
D18: PROD | E18: IMPROD | F18: PROD | G18: IMPROD
G23: (A) TOTAL | H23: =SUM(H19:H22) -> 0
A24: MÃO DE OBRA | E24: UNID | F24: QUANTIDADE | G24: SALÁRIO BASE | H24: CUSTO HORÁRIO
E25: PROD | F25: IMPROD
A28: 1213 CARPINTEIRO DE FORMAS | E28: h | F28: 0.25 | G28: 5.51 | H28: =F28*G28 -> 1.3775
A29: 6117 AJUDANTE DE CARPINTEIRO | E29: h | F29: 0.25 | G29: 4.14 | H29: =F29*G29 -> 1.035
G35: (B1) TOTAL | H35: =SUM(H26:H34) -> 2.4125
A36: (B2)ENCARGOS SOCIAIS | D36: 1.1066036 | H36: =ROUND(H35*D36,2) -> 2.67
E37: (B) TOTAL MDO (B1+B2) | H37: =+H35+H36 -> 5.0825
A38: MATERIAIS | E38: UNID | F38: QUANTIDADE | G38: CUSTO UNITÁRIO | H38: CUSTO TOTAL
E39: PROD | F39: IMPROD
A41: 5069 PREGO DE ACO 17 X 27 | E41: kg | F41: 0.1 | G41: 7.3 | H41: =F41*G41 -> 0.73
A42: 4435 PECA DE MADEIRA ( PINHO) 1A QUALIDADE 3,75 X 22,5CM NAO APARELHADA
E43: m | F43: 2 | G43: 6.43 | H43: =F43*G43 -> 12.86
A44: 4813 PLACA DE OBRA (IDENTIFICACAO) PARA CONSTRUCAO CIVIL EM CHAPA GALVANIZADA NUM 22 | E44: m² | F44: 1 | G44: 200 | H44: =F44*G44 -> 200
G46: (C) TOTAL | H46: =SUM(H40:H45) -> 213.59
A47: TRANSPORTE | D47: DTM | E47: UNIDADE | F47: QUANT. | G47: CUSTO UNITÁRIO | H47: CUSTO TOTAL
E48: PROD | F48: IMPROD
G53: (D)TOTAL | H53: =SUM(H49:H52) -> 0
A54: PREÇO UNITÁRIO TOTAL (A) + (B) + (C) + (D) | G54: R$ | H54: =+H23+H37+H46+H53 -> 218.6725
A55: BONIFICAÇÃO | D55: 0.2623 | G55: R$ | H55: =ROUND(H54*D55,2) -> 57.36
A56: CUSTO UNITÁRIO TOTAL | G56: R$ | H56: =+H54+H55 -> 276.0325
A57: Engenheiro Civil - LUÍS FERNANDO DIAS - Responsável Técnico - CREA-RJ 1985100024
A58: Observações: O preço unitário total, inclui todos os custos diretos e indiretos

Sheet 1.6
A9: COMPOSIÇÃO ANALÍTICA DE PREÇOS
A10: TÍTULO: | G10: ='I-1'!G10:H10 -> Data Base
A11: =PLANILHA!#REF! -> #REF! | G11: ='I-1'!G11:H11 -> 41671
A13: Órgão: Infraero - Empresa Brasileira de Infraestrutura Aeroportuária
A14: Local: Aeroporto de Vitória - SBVT | G14: ='I-1'!G16:H16 -> SINAPI - FEV 2014
A15: GERÊNCIA DE MANUTENÇÃO - VTMN
A16: CÓDIGO: Item 1.6 | B16: =PLANILHA!#REF! -> #REF! | H16: Unidade un
A17: EQUIPAMENTO | B17: Unid. | C17: QUANT | D17: UTILIZAÇÃO | F17: CUSTO OPERACIONAL | H17: CUSTO HORÁRIO
D18: PROD | E18: IMPROD | F18: PROD | G18: IMPROD
G23: (A) TOTAL | H23: =SUM(H19:H22) -> 0
A24: MÃO DE OBRA | E24: UNID | F24: QUANTIDADE | G24: SALÁRIO BASE | H24: CUSTO HORÁRIO
E25: PROD | F25: IMPROD
A27: 1213 CARPINTEIRO DE FORMAS | E27: h | F27: 2 | G27: 5.51 | H27: =F27*G27 -> 11.02
G35: (B1) TOTAL | H35: =SUM(H26:H34) -> 11.02
A36: (B2)ENCARGOS SOCIAIS | D36: 1.1066036 | H36: =ROUND(H35*D36,2) -> 12.19
E37: (B) TOTAL MDO (B1+B2) | H37: =+H35+H36 -> 23.21
A38: MATERIAIS | E38: UNID | F38: QUANTIDADE | G38: CUSTO UNITÁRIO | H38: CUSTO TOTAL
E39: PROD | F39: IMPROD
A40: 1344 CHAPA MADEIRA COMPENSADA PLASTIFICADA 2,2 X 1,1M X 6MM
E41: m² | F41: 0.01 | G41: 29.82 | H41: =F41*G41 -> 0.2982
A45: 4439 PECA DE MADEIRA DE LEI 1A QUALIDADE 2,5 X 30CM NAO APARELHADA
E46: m | F46: 0.02 | G46: 28.53 | H46: =F46*G46 -> 0.5706
A47: 5066 PREGO DE ACO 12 X 12 | E47: kg | F47: 0.02 | G47: 8.98 | H47: =F47*G47 -> 0.1796
A48: 20247 PREGO DE ACO 15 X 15 C/ CABECA | E48: kg | F48: 0.02 | G48: 7.61 | H48: =F48*G48 -> 0.1522
A49: 5069 PREGO DE ACO 17 X 27 | E49: kg | F49: 0.02 | G49: 6.65 | H49: =F49*G49 -> 0.133
A52: 7170 TELA DE NYLON OU PLÁSTICA COM MALHA DE 5 MM, PARA PROTEÇÃO DE OBRA.
E53: m² | F53: 7.93 | G53: 1.55 | H53: =F53*G53 -> 12.2915
G57: (C) TOTAL | H57: =SUM(H40:H56) -> 13.6251
A58: TRANSPORTE | D58: DTM | E58: UNIDADE | F58: QUANT. | G58: CUSTO UNITÁRIO | H58: CUSTO TOTAL
E59: PROD | F59: IMPROD
G64: (D)TOTAL | H64: =SUM(H60:H63) -> 0
A65: PREÇO UNITÁRIO TOTAL (A) + (B) + (C) + (D) | G65: R$ | H65: =+H23+H37+H57+H64 -> 36.8351
A66: BONIFICAÇÃO | D66: 0.2623 | G66: R$ | H66: =ROUND(H65*D66,2) -> 9.66
A67: CUSTO UNITÁRIO TOTAL | G67: R$ | H67: =+H65+H66 -> 46.4951
A68: Engenheiro Civil - LUÍS FERNANDO DIAS - Responsável Técnico - CREA-RJ 1985100024
A69: Observações: O preço unitário total, inclui todos os custos diretos e indiretos.

Sheet 2.1
A9: COMPOSIÇÃO ANALÍTICA DE PREÇOS
A10: TÍTULO: | G10: Data Base
A11: =PLANILHA!#REF! -> #REF! | G11: =CAPA!C8 -> 41671
A13: Órgão: Infraero - Empresa Brasileira de Infraestrutura Aeroportuária
A14: Local: Aeroporto de Vitória - SBVT | G14: SINAPI - FEV 2014
A15: GERÊNCIA DE MANUTENÇÃO - VTMN
A16: Item: 2.1 | B16: =PLANILHA!#REF! -> #REF! | H16: Unidade m
A17: EQUIPAMENTO | B17: Unid. | C17: QUANT | D17: UTILIZAÇÃO | F17: CUSTO OPERACIONAL | H17: CUSTO HORÁRIO
D18: PROD | E18: IMPROD | F18: PROD | G18: IMPROD
G30: (A) TOTAL | H30: =SUM(H19:H29) -> 0
A31: MÃO DE OBRA | D31: SINAPI | E31: UNID | F31: QUANTIDADE | G31: SALÁRIO BASE | H31: CUSTO HORÁRIO
E32: PROD | F32: IMPROD
A34: ENCARREGADO GERAL | D34: 4083 | E34: h | F34: 0.2 | G34: 12.38 | H34: =F34*G34 -> 2.476
A35: SERVENTE | D35: 6127 | E35: h | F35: 0.4 | G35: 4.01 | H35: =F35*G35 -> 1.604
G42: (B1) TOTAL | H42: =SUM(H33:H41) -> 4.08
A43: (B2)ENCARGOS SOCIAIS | D43: =Enc_Sociais!C43 -> 1.1066036 | H43: =ROUND(H42*D43,2) -> 4.51
E44: (B) TOTAL MDO (B1+B2) | H44: =+H42+H43 -> 8.59
A45: MATERIAIS | E45: UNID | F45: QUANTIDADE | G45: CUSTO UNITÁRIO | H45: CUSTO TOTAL
E46: PROD | F46: IMPROD
G51: (C) TOTAL | H51: =SUM(H47:H50) -> 0
A52: TRANSPORTE | E52: UNIDADE | F52: QUANT. | G52: CUSTO UNITÁRIO | H52: CUSTO TOTAL
E53: PROD | F53: IMPROD
G58: (D)TOTAL | H58: =SUM(H54:H57) -> 0
A59: PREÇO UNITÁRIO TOTAL (A) + (B) + (C) + (D) | G59: R$ | H59: =+H30+H44+H51+H58 -> 8.59
A60: BONIFICAÇÃO | D60: 0.2623 | G60: R$ | H60: =ROUND(H59*D60,2) -> 2.25
A61: CUSTO UNITÁRIO TOTAL | G61: R$ | H61: =+H59+H60 -> 10.84
A62: Engenheiro Civil - LUÍS FERNANDO DIAS - Responsável Técnico - CREA-RJ 1985100024
A63: Observações: O preço unitário total, inclui todos os custos diretos e indiretos

Sheet 2.2
A9: COMPOSIÇÃO ANALÍTICA DE PREÇOS
A10: TÍTULO: | G10: Data Base
A11: =PLANILHA!#REF! -> #REF! | G11: =CAPA!C8 -> 41671
A13: Órgão: Infraero - Empresa Brasileira de Infraestrutura Aeroportuária
A14: Local: Aeroporto de Vitória - SBVT | G14: SINAPI - FEV 2014
A15: GERÊNCIA DE MANUTENÇÃO - VTMN
A16: Item: 2.2 | B16: =PLANILHA!#REF! -> #REF! | H16: Unidade m²
A17: EQUIPAMENTO | B17: Unid. | C17: QUANT | D17: UTILIZAÇÃO | F17: CUSTO OPERACIONAL | H17: CUSTO HORÁRIO
D18: PROD | E18: IMPROD | F18: PROD | G18: IMPROD
G26: (A) TOTAL | H26: =SUM(H19:H25) -> 0
A27: MÃO DE OBRA | D27: SINAPI | E27: UNID | F27: QUANTIDADE | G27: SALÁRIO BASE | H27: CUSTO HORÁRIO
E28: PROD | F28: IMPROD
A29: Encarregado Geral | D29: 4083 | E29: h | F29: 0.27 | G29: 12.38 | H29: =F29*G29 -> 3.3426
A30: Servente | D30: 6127 | E30: h | F30: 0.53 | G30: 4.01 | H30: =F30*G30 -> 2.1253
G38: (B1) TOTAL | H38: =SUM(H29:H37) -> 5.4679
A39: (B2)ENCARGOS SOCIAIS | D39: =Enc_Sociais!C43 -> 1.1066036 | H39: =ROUND(H38*D39,2) -> 6.05
E40: (B) TOTAL MDO (B1+B2) | H40: =+H38+H39 -> 11.5179
A41: MATERIAIS | E41: UNID | F41: QUANTIDADE | G41: CUSTO UNITÁRIO | H41: CUSTO TOTAL
E42: PROD | F42: IMPROD
G45: (C) TOTAL | H45: =SUM(H43:H44) -> 0
A46: TRANSPORTE | D46: DTM | E46: UNIDADE | F46: QUANT. | G46: CUSTO UNITÁRIO | H46: CUSTO TOTAL
E47: PROD | F47: IMPROD
G52: (D)TOTAL | H52: =SUM(H48:H51) -> 0
A53: PREÇO UNITÁRIO TOTAL (A) + (B) + (C) + (D) | G53: R$ | H53: =+H26+H40+H45+H52 -> 11.5179
A54: BONIFICAÇÃO | D54: 0.2623 | G54: R$ | H54: =ROUND(H53*D54,2) -> 3.02
A55: CUSTO UNITÁRIO TOTAL | G55: R$ | H55: =+H53+H54 -> 14.5379
A56: Engenheiro Civil - LUÍS FERNANDO DIAS - Responsável Técnico - CREA-RJ 1985100024
A57: Observações: O preço unitário total, inclui todos os custos diretos e indiretos

Sheet 2.3
A9: COMPOSIÇÃO ANALÍTICA DE PREÇOS
A10: TÍTULO: | G10: Data Base
A11: =PLANILHA!#REF! -> #REF! | G11: =CAPA!C8 -> 41671
A13: Órgão: Infraero - Empresa Brasileira de Infraestrutura Aeroportuária
A14: Local: Aeroporto de Vitória - SBVT | G14: ='I-1'!G16:H16 -> SINAPI - FEV 2014
A15: GERÊNCIA DE MANUTENÇÃO - VTMN
A16: Item 2.3 | B16: =PLANILHA!#REF! -> #REF! | H16: Unidade un
A17: EQUIPAMENTO | B17: Unid. | C17: QUANT | D17: UTILIZAÇÃO | F17: CUSTO OPERACIONAL | H17: CUSTO HORÁRIO
D18: PROD | E18: IMPROD | F18: PROD | G18: IMPROD
G24: (A) TOTAL | H24: =SUM(H19:H23) -> 0
A25: MÃO DE OBRA | D25: sinapi | E25: UNID | F25: QUANTIDADE | G25: SALÁRIO BASE | H25: CUSTO HORÁRIO
E26: PROD | F26: IMPROD
A28: Encarregado Geral | D28: 4083 | E28: h | F28: 0.5 | G28: 12.38 | H28: =F28*G28 -> 6.19
A29: servente | D29: 6127 | E29: h | F29: 1 | G29: 4.01 | H29: =F29*G29 -> 4.01
A30: pedreiro | D30: 4750 | E30: h | F30: 1 | G30: 5.51 | H30: =F30*G30 -> 5.51
G36: (B1) TOTAL | H36: =SUM(H27:H35) -> 15.71
A37: (B2)ENCARGOS SOCIAIS | D37: =Enc_Sociais!C43 -> 1.1066036 | H37: =ROUND(H36*D37,2) -> 17.38
E38: (B) TOTAL MDO (B1+B2) | H38: =+H36+H37 -> 33.09
A39: MATERIAIS | D39: SINAPI | E39: UNID | F39: QUANTIDADE | G39: CUSTO UNITÁRIO | H39: CUSTO TOTAL
E40: PROD | F40: IMPROD
A41: ARGAMASSA PARA LEVANTAMENTO E REBAIXAMENTO DAS CAIXAS DE PASSAGEM, CIMENTO E AREIA TRAÇO 1:3. | D41: 129 | E41: kg | F41: 3 | G41: 2.81 | H41: =F41*G41 -> 8.43
G43: (C) TOTAL | H43: =SUM(H41:H42) -> 8.43
A44: TRANSPORTE | D44: DTM | E44: UNIDADE | F44: QUANT. | G44: CUSTO UNITÁRIO | H44: CUSTO TOTAL
E45: PROD | F45: IMPROD
G50: (D)TOTAL | H50: =SUM(H46:H49) -> 0
A51: PREÇO UNITÁRIO TOTAL (A) + (B) + (C) + (D) | G51: R$ | H51: =+H24+H38+H43+H50 -> 41.52
A52: BONIFICAÇÃO | D52: 0.2623 | G52: R$ | H52: =ROUND(H51*D52,2) -> 10.89
A53: CUSTO UNITÁRIO TOTAL | G53: R$ | H53: =+H51+H52 -> 52.41
A54: Engenheiro Civil - LUÍS FERNANDO DIAS - Responsável Técnico - CREA-RJ 1985100024
A55: Observações: O preço unitário total, inclui todos os custos diretos e indiretos

Sheet 2.4
A9: COMPOSIÇÃO ANALÍTICA DE PREÇOS
A10: TÍTULO: | G10: ='I-1'!G10:H10 -> Data Base
A11: =PLANILHA!#REF! -> #REF! | G11: ='I-1'!G11:H11 -> 41671
A13: Órgão: Infraero - Empresa Brasileira de Infraestrutura Aeroportuária
A14: Local: Aeroporto de Vitória - SBVT | G14: ='I-1'!G16:H16 -> SINAPI - FEV 2014
A15: GERÊNCIA DE MANUTENÇÃO - VTMN
A16: CÓDIGO: Item 2.4 | B16: =PLANILHA!#REF! -> #REF! | H16: Unidade m
A17: EQUIPAMENTO | B17: Unid. | C17: QUANT | D17: UTILIZAÇÃO | F17: CUSTO OPERACIONAL | H17: CUSTO HORÁRIO
D18: PROD | E18: IMPROD | F18: PROD | G18: IMPROD
G27: (A) TOTAL | H27: =SUM(H19:H26) -> 0
A28: MAO DE OBRA | D28: sinapi | E28: UNID | F28: QUANTIDADE | G28: SALÁRIO BASE | H28: CUSTO HORÁRIO
E29: PROD | F29: IMPROD
G35: (B1) TOTAL | H35: =SUM(H30:H34) -> 0
A36: (B2)ENCARGOS SOCIAIS | D36: =Enc_Sociais!C43 -> 1.1066036 | H36: =ROUND(H35*D36,2) -> 0
E37: (B) TOTAL MDO (B1+B2) | H37: =+H35+H36 -> 0
A38: SERVIÇOS | D38: SINAPI | E38: UNID | F38: QUANTIDADE | G38: CUSTO UNITÁRIO | H38: CUSTO TOTAL
E39: PROD | F39: IMPROD
A40: ASSENTAMENTO DE MEIO FIO PREMOLDADO, INCLUINDO ESCAVACAO. | D40: 83717 | E40: m | F40: 1 | G40: 9.97 | H40: =F40*G40 -> 9.97
G42: (C) TOTAL | H42: =SUM(H40:H41) -> 9.97
A43: MATERIAIS | D43: SINAPI | E43: UNIDADE | F43: QUANT. | G43: CUSTO UNITÁRIO | H43: CUSTO TOTAL
E44: PROD | F44: IMPROD
A46: MEIO FIO RETO DE CONCRETO ( PADRAO PMV ) | D46: 4064 | E46: m | F46: 0.2030075 | G46: 17 | H46: =F46*G46 -> 3.4511275
G49: (D)TOTAL | H49: =SUM(H45:H48) -> 3.4511275
A50: PREÇO UNITÁRIO TOTAL (A) + (B) + (C) + (D) | G50: R$ | H50: =+H27+H37+H42+H49 -> 13.421128
A51: BONIFICAÇÃO | D51: 0.2623 | G51: R$ | H51: =ROUND(H50*D51,2) -> 3.52
A52: CUSTO UNITÁRIO TOTAL | G52: R$ | H52: =+H50+H51 -> 16.941128
A53: Engenheiro Civil - LUÍS FERNANDO DIAS - Responsável Técnico - CREA-RJ 1985100024
A54: Observações: O preço unitário total, inclui todos os custos diretos e indiretos

Sheet 3.1
A9: COMPOSIÇÃO ANALÍTICA DE PREÇOS
A10: TÍTULO: | G10: ='I-1'!G10:H10 -> Data Base
A11: =PLANILHA!#REF! -> #REF! | G11: ='I-1'!G11:H11 -> 41671
A13: Órgão: Infraero - Empresa Brasileira de Infraestrutura Aeroportuária
A14: Local: Aeroporto de Vitória - SBVT | G14: SINAPI - FEV 2014
A15: GERÊNCIA DE MANUTENÇÃO - VTMN
A16: Item: 3.1 | B16: =PLANILHA!#REF! -> #REF! | H16: Unidade m²
A17: EQUIPAMENTO | B17: Unid. | C17: QUANT | D17: UTILIZAÇÃO | F17: CUSTO OPERACIONAL | H17: CUSTO HORÁRIO
D18: PROD | E18: IMPROD | F18: PROD | G18: IMPROD
G29: (A) TOTAL | H29: =SUM(H19:H28) -> 0
A30: MÃO DE OBRA | E30: UNID | F30: QUANTIDADE | G30: SALÁRIO BASE | H30: CUSTO HORÁRIO
E31: PROD | F31: IMPROD
G41: (B1) TOTAL | H41: =SUM(H32:H40) -> 0
A42: (B2)ENCARGOS SOCIAIS | D42: =Enc_Sociais!C43 -> 1.1066036 | H42: =ROUND(H41*D42,2) -> 0
E43: (B) TOTAL MDO (B1+B2) | H43: =+H41+H42 -> 0
A44: SERVIÇOS | E44: UNID | F44: QUANTIDADE | G44: CUSTO UNITÁRIO | H44: CUSTO TOTAL
E45: PROD | F45: IMPROD
A46: REGULARIZAÇÃO DA BASE DA CALÇADA E COMPACTAÇÃO MANUAL DO TERRENO COM SOQUETE | D46: 5622 | E46: m² | F46: 1 | G46: 2.27 | H46: =F46*G46 -> 2.27
A47: FORNECIMENTO E INSTALAÇÃO LONA PLÁSTICA PRETA, PARA IMPERMEABILIZAÇÃO, ESPESSURA 150 MICRAS. | D47: 68053 | E47: m² | F47: 1 | G47: 2.82 | H47: =F47*G47 -> 2.82
A48: ARMAÇÃO EM TELA SOLDADA Q92 (AÇO CA-60 Ø4,2mm C/ 15CM) | D48: 73994/001 | E48: m² | F48: 1.48 | G48: 4.69 | H48: =F48*G48 -> 6.9412
G52: (C) TOTAL | H52: =SUM(H46:H51) -> 12.0312
A53: TRANSPORTE | D53: DTM | E53: UNIDADE | F53: QUANT. | G53: CUSTO UNITÁRIO | H53: CUSTO TOTAL
E54: PROD | F54: IMPROD
G60: (D)TOTAL | H60: =SUM(H55:H59) -> 0
A61: PREÇO UNITÁRIO TOTAL (A) + (B) + (C) + (D) | G61: R$ | H61: =+H29+H43+H52+H60 -> 12.0312
A62: BONIFICAÇÃO | D62: 0.2623 | G62: R$ | H62: =ROUND(H61*D62,2) -> 3.16
A63: CUSTO UNITÁRIO TOTAL | G63: R$ | H63: =+H61+H62 -> 15.1912
A64: Engenheiro Civil - LUÍS FERNANDO DIAS - Responsável Técnico - CREA-RJ 1985100024
A65: Observações: O preço unitário total, inclui todos os custos diretos e indiretos

Sheet 3.2
A9: COMPOSIÇÃO ANALÍTICA DE PREÇOS
A10: TÍTULO: | G10: Data Base
A11: =PLANILHA!#REF! -> #REF! | G11: =CAPA!C8 -> 41671
A13: Órgão: Infraero - Empresa Brasileira de Infraestrutura Aeroportuária
A14: Local: Aeroporto de Vitória - SBVT | G14: SINAPI - FEV 2014
A15: GERÊNCIA DE MANUTENÇÃO - VTMN
A16: Item: 03 | B16: =PLANILHA!#REF! -> #REF! | H16: Unidade m²
A17: EQUIPAMENTO | B17: Unid. | C17: QUANT | D17: UTILIZAÇÃO | F17: CUSTO OPERACIONAL | H17: CUSTO HORÁRIO
D18: PROD | E18: IMPROD | F18: PROD | G18: IMPROD
G29: (A) TOTAL | H29: =SUM(H19:H28) -> 0
A30: MÃO DE OBRA | E30: UNID | F30: QUANTIDADE | G30: SALÁRIO BASE | H30: CUSTO HORÁRIO
E31: PROD | F31: IMPROD
G41: (B1) TOTAL | H41: =SUM(H32:H40) -> 0
A42: (B2)ENCARGOS SOCIAIS | D42: =Enc_Sociais!C43 -> 1.1066036 | H42: =ROUND(H41*D42,2) -> 0
E43: (B) TOTAL MDO (B1+B2) | H43: =+H41+H42 -> 0
A44: MATERIAIS | E44: UNID | F44: QUANTIDADE | G44: CUSTO UNITÁRIO | H44: CUSTO TOTAL
E45: PROD | F45: IMPROD
A46: PISO EM CONCRETO 20MPA, INCLUSIVE LANÇAMENTO E ADENSAMENTO. | D46: 74138/002 | E46: m² | F46: 1 | G46: 31.152 | H46: =F46*G46 -> 31.152
G52: (C) TOTAL | H52: =SUM(H46:H51) -> 31.152
A53: TRANSPORTE | D53: DTM | E53: UNIDADE | F53: QUANT. | G53: CUSTO UNITÁRIO | H53: CUSTO TOTAL
E54: PROD | F54: IMPROD
G59: (D)TOTAL | H59: =SUM(H55:H58) -> 0
A60: PREÇO UNITÁRIO TOTAL (A) + (B) + (C) + (D) | G60: R$ | H60: =+H29+H43+H52+H59 -> 31.152
A61: BONIFICAÇÃO | D61: 0.2623 | G61: R$ | H61: =ROUND(H60*D61,2) -> 8.17
A62: CUSTO UNITÁRIO TOTAL | G62: R$ | H62: =+H60+H61 -> 39.322
A63: Engenheiro Civil - LUÍS FERNANDO DIAS - Responsável Técnico - CREA-RJ 1985100024
A64: Observações: O preço unitário total, inclui todos os custos diretos e indiretos

Sheet 3.3
A9: COMPOSIÇÃO ANALÍTICA DE PREÇOS
A10: TÍTULO: | G10: Data Base
A11: =PLANILHA!#REF! -> #REF! | G11: =CAPA!C8 -> 41671
A13: Órgão: Infraero - Empresa Brasileira de Infraestrutura Aeroportuária
A14: Local: Aeroporto de Vitória - SBVT | G14: SINAPI - FEV 2014
A15: GERÊNCIA DE MANUTENÇÃO - VTMN
A16: Item 3.3 | B16: =PLANILHA!#REF! -> #REF! | H16: Unidade m²
A17: EQUIPAMENTO | B17: Unid. | C17: QUANT | D17: UTILIZAÇÃO | F17: CUSTO OPERACIONAL | H17: CUSTO HORÁRIO
D18: PROD | E18: IMPROD | F18: PROD | G18: IMPROD
G29: (A) TOTAL | H29: =SUM(H19:H28) -> 0
A30: MÃO DE OBRA | E30: UNID | F30: QUANTIDADE | G30: SALÁRIO BASE | H30: CUSTO HORÁRIO
E31: PROD | F31: IMPROD
G41: (B1) TOTAL | H41: =SUM(H32:H40) -> 0
A42: (B2)ENCARGOS SOCIAIS | D42: =Enc_Sociais!C43 -> 1.1066036 | H42: =ROUND(H41*D42,2) -> 0
E43: (B) TOTAL MDO (B1+B2) | H43: =+H41+H42 -> 0
A44: MATERIAIS | E44: UNID | F44: QUANTIDADE | G44: CUSTO UNITÁRIO | H44: CUSTO TOTAL
E45: PROD | F45: IMPROD
A46: PISO EM LADRILHO HIDRAULICO TIPO PODOTÁTIL DE ALERTA, 20X20CM ASSENTADO SOBRE ARGAMASSA DE CIMENTO COLANTE REJUNTADO COM CIMENTO COMUM | D46: 73629 | E46: m² | F46: 1 | G46: 42.61 | H46: =F46*G46 -> 42.61
G50: (C) TOTAL | H50: =SUM(H46:H49) -> 42.61
A51: TRANSPORTE | D51: DTM | E51: UNIDADE | F51: QUANT. | G51: CUSTO UNITÁRIO | H51: CUSTO TOTAL
E52: PROD | F52: IMPROD
G57: (D)TOTAL | H57: =SUM(H53:H56) -> 0
A58: PREÇO UNITÁRIO TOTAL (A) + (B) + (C) + (D) | G58: R$ | H58: =+H29+H43+H50+H57 -> 42.61
A59: BONIFICAÇÃO | D59: 0.2623 | G59: R$ | H59: =ROUND(H58*D59,2) -> 11.18
A60: CUSTO UNITÁRIO TOTAL | G60: R$ | H60: =+H58+H59 -> 53.79
A61: Engenheiro Civil - LUÍS FERNANDO DIAS - Responsável Técnico - CREA-RJ 1985100024
A62: Observações: O preço unitário total, inclui todos os custos diretos e indiretos

Sheet 3.4
A9: COMPOSIÇÃO ANALÍTICA DE PREÇOS
A10: TÍTULO: | G10: Data Base
A11: =PLANILHA!#REF! -> #REF! | G11: =CAPA!C8 -> 41671
A13: Órgão: Infraero - Empresa Brasileira de Infraestrutura Aeroportuária
A14: Local: Aeroporto de Vitória - SBVT | G14: SINAPI - FEV 2014
A15: GERÊNCIA DE MANUTENÇÃO - VTMN
A16: Item: 3.4 | B16: =PLANILHA!#REF! -> #REF! | H16: Unidade m²
A17: EQUIPAMENTO | B17: Unid. | C17: QUANT | D17: UTILIZAÇÃO | F17: CUSTO OPERACIONAL | H17: CUSTO HORÁRIO
D18: PROD | E18: IMPROD | F18: PROD | G18: IMPROD
A19: CAMINHÃO BASCULANTE 5,0M3/11T DIESEL TIPO MERCEDES 142HP LK-1214 OU EQUIV (INCL MANUT/OPERACAO) cod 1133 | B19: h | C19: 0.01 | D19: 37.81 | H19: =C19*D19 -> 0.3781
A20: RETROESCAVADEIRA C/ CARREGADEIRA SOBRE PNEUS 75HP C/CONVERSOR DE TORQUE (INCL MANUTENCAO/OPERACAO E COMBUSTÍVEL) cod 6044 | B20: h | C20: 0.0005 | D20: 83.16 | H20: =C20*D20 -> 0.04158
G23: (A) TOTAL | H23: =SUM(H19:H22) -> 0.41968
A24: MÃO DE OBRA | E24: UNID | F24: QUANTIDADE | G24: SALÁRIO BASE | H24: CUSTO HORÁRIO
E25: PROD | F25: IMPROD
A27: Encarregado geral | D27: 4083 | E27: h | F27: 0.05 | G27: 12.38 | H27: =F27*G27 -> 0.619
A28: Servente | D28: 6127 | E28: h | F28: 0.25 | G28: 4.01 | H28: =F28*G28 -> 1.0025
A29: Pedreiro | D29: 4750 | E29: h | F29: 0.05 | G29: 5.51 | H29: =F29*G29 -> 0.2755
G32: (B1) TOTAL | H32: =SUM(H26:H31) -> 1.897
A33: (B2)ENCARGOS SOCIAIS | D33: =Enc_Sociais!C43 -> 1.1066036 | H33: =ROUND(H32*D33,2) -> 2.1
E34: (B) TOTAL MDO (B1+B2) | H34: =+H32+H33 -> 3.997
A35: MATERIAIS | E35: UNID | F35: QUANTIDADE | G35: CUSTO UNITÁRIO | H35: CUSTO TOTAL
E36: PROD | F36: IMPROD
G39: (C) TOTAL | H39: =SUM(H37:H38) -> 0
A40: TRANSPORTE | D40: DTM | E40: UNIDADE | F40: QUANT. | G40: CUSTO UNITÁRIO | H40: CUSTO TOTAL
E41: PROD | F41: IMPROD
G46: (D)TOTAL | H46: =SUM(H42:H45) -> 0
A47: PREÇO UNITÁRIO TOTAL (A) + (B) + (C) + (D) | G47: R$ | H47: =+H23+H34+H39+H46 -> 4.41668
A48: BONIFICAÇÃO | D48: 0.2623 | G48: R$ | H48: =ROUND(H47*D48,2) -> 1.16
A49: CUSTO UNITÁRIO TOTAL | G49: R$ | H49: =+H47+H48 -> 5.57668
A50: Engenheiro Civil - LUÍS FERNANDO DIAS - Responsável Técnico - CREA-RJ 1985100024
A51: Observações: O preço unitário total, inclui todos os custos diretos e indiretos

Sheet BDI
A1: PLANILHA DE COMPOSIÇÃO DE BDI - ANEXO III DA NT nº. 57/CNCG/EPOE/LCNS/CCCE-3/2012
A3: OBRAS E SERVIÇOS DE ENGENHARIA
A6: ITEM | B6: DISCRIMINAÇÃO | C6: %
A10: A | B10: GRUPO A | C10: =SUM(C12:C14) -> 0.0607
A12: 1 | B12: Administração Central | C12: 0.055
A13: 2 | B13: Riscos | C13: 0.0057
A19: B | B19: GRUPO B | C19: =SUM(C21:C24) -> 0.099
A21: 3 | B21: Seguro de Risco de Engenharia | C21: 0.006
A22: 4 | B22: Garantia | C22: 0.0021
A23: 5 | B23: Lucro Bruto | C23: 0.085
A24: 6 | B24: Despesas Financeiras | C24: 0.0059
A26: C | B26: GRUPO C | C26: =SUM(C28:C31) -> 0.0765
A28: 7 | B28: PIS | C28: 0.0065
A29: 8 | B29: COFINS | C29: 0.03
A30: 9 | B30: ISS | C30: 0.04
A34: BDI | B34: BDI = ((1+A)x(1+B)/(1-C))-1)*100 | C34: =(((1+C10)*(1+C19))/(1-C26))-1 -> 0.2622732
A35: ISS adotado conforme artigo de Lei da Prefeitura Municipal de Vitória/ES.

Sheet Enc_Sociais
A1: OBRAS E SERVIÇOS DE ENGENHARIA
A2: PLANILHA DE COMPOSIÇÃO DE ENCARGOS SOCIAIS - HORISTA
B3: ANEXO I DA NT nº. 57/CNCG/EPOE/LCNS/CCCE-3/2012
B4: ENCARGOS SOCIAIS
A5: GRUPO A | C5: %
A6: 01 | B6: INSS | C6: 0.2
A7: 02 | B7: SESI ou SESC | C7: 0.015
A8: 03 | B8: SENAI ou SENAC | C8: 0.01
A9: 04 | B9: INCRA | C9: 0.002
A10: 05 | B10: Salário Educação | C10: 0.025
A11: 06 | B11: FGTS | C11: 0.08
A12: 07 | B12: Seguro Acidente do Trabalho/SAT/INSS | C12: 0.03
A13: 08 | B13: SEBRAE | C13: 0.006
A14: 09 | B14: SECONCI | C14: 0.01
B15: Total do Primeiro Grupo | C15: =SUM(C6:C14) -> 0.378
A17: GRUPO B
A18: 10 | B18: Férias | C18: 0.1
A19: 11 | B19: Abono constitucional de Férias | C19: 0.0333
A20: 12 | B20: Auxílio Doença | C20: 0.0167
A21: 13 | B21: Licença Paternidade | C21: 0.0003
A22: 14 | B22: Faltas Legais | C22: 0.0033
A23: 15 | B23: Acidentes de Trabalho | C23: 0.004
A24: 16 | B24: Aviso Prévio Trabalhado | C24: 0.0186
A25: 17 | B25: 13° Salário | C25: 0.1
A26: 18 | B26: Descanso Semanal Remunerado | C26: 0.2
B27: Total do Segundo Grupo | C27: =SUM(C18:C26) -> 0.4762
A29: GRUPO C
A30: 19 | B30: Aviso Prévio Indenizado | C30: 0.0205
A31: 20 | B31: Indenização Adicional | C31: 0.001
A32: 21 | B32: Indenização de FGTS | C32: 0.0432
B33: Total do Terceiro Grupo | C33: =SUM(C30:C32) -> 0.0647
A35: GRUPO D
A36: 22 | B36: Incidência do Grupo A sobre os itens do Grupo B | C36: =C15*C27 -> 0.1800036
B37: Total do quarto grupo | C37: =SUM(C36) -> 0.1800036
A39: GRUPO E
A40: 23 | B40: Incidência do Grupo A sobre o item 19 do Grupo B | C40: 0.0077
B41: Total do quinto grupo | C41: =SUM(C40) -> 0.0077
B43: TOTAL GERAL ENCARGOS SOCIAIS | C43: =SUM(C41+C37+C33+C27+C15) -> 1.1066036

Sheet cronograma
C1: CRONOGRAMA FÍSICO - FINANCEIRO
B2: EMPRESA BRASILEIRA DE INFRAESTRUTURA AEROPORTUÁRIA | C2: =PLANILHA!#REF! -> #REF!
B4: SUPERINTENDÊNCIA DO AEROPORTO DE VITÓRIA - SBVT | C4: DATA: 31/03/2014
C5: INÍCIO: | E5: TÉRMINO:
B6: GERENCIA DE MANUTENÇÃO | C6: PRAZO: 28 DIAS | E6: Nº. VT.01/202.98/40331.00
C7: Prep.: Engº. Luís Fernando | E7: Ver.:
C8: R$ TOTAL | D8: 1º SEMANA | E8: 2º SEMANA | F8: 3º SEMANA | G8: 4º SEMANA
A9: I | B9: MOBILIZAÇÃO E DESMOBILIZAÇÃO MÁQUINAS, EQUIPAMENTOS E DA EQUIPE DE PAVIMENTAÇÃO | C9: =PLANILHA!#REF! -> #REF! | D9: 0.5 | G9: 0.5
D10: =D9*C9 -> #REF! | G10: =G9*C9 -> #REF!
A11: II | B11: =PLANILHA!#REF! -> #REF! | C11: =PLANILHA!#REF! -> #REF! | D11: 0.5 | E11: 0.5
D12: =D11*C11 -> #REF! | E12: =E11*C11 -> #REF!
A13: III | B13: =PLANILHA!#REF! -> #REF! | C13: =PLANILHA!#REF! -> #REF! | E13: 0.5 | F13: 0.5
E14: =E13*C13 -> #REF! | F14: =F13*C13 -> #REF!
A15: IV | B15: =PLANILHA!#REF! -> #REF! | C15: =PLANILHA!#REF! -> #REF! | F15: 0.5 | G15: 0.5
B16: INSTALAÇÃO DO CANTEIRO DE OBRA | F16: =F15*C15 -> #REF! | G16: =G15*C15 -> #REF!
B17: TOTAL GERAL | C17: =C9+C11+C13+C15 -> #REF!
B20: VALORES EM % | D20: =D23/C17 -> #REF! | E20: =E23/C17 -> #REF! | F20: =F23/C17 -> #REF! | G20: =G23/C17 -> #REF!
B21: VALORES COM BDI 26,23% | C21: =PLANILHA!F60 -> 95964.675 | D21: =(D10)*1.2623 -> #REF! | E21: =(E12+E14)*1.2623 -> #REF! | F21: =(F14)*1.2623 -> #REF! | G21: =(G10+G16)*1.2623 -> #REF!
B22: VALORES EM % acumulado | D22: =D20 -> #REF! | E22: =E20+D22 -> #REF! | F22: =D20+E20+F20 -> #REF! | G22: =D20+E20+F20+G20 -> #REF!
B23: VALORES EM REAIS | D23: =D10+D12 -> #REF! | E23: =E12+E14 -> #REF! | F23: =F14+F16 -> #REF! | G23: =G10+G16 -> #REF!
B24: VALORES EM REAIS acumulado | D24: =D21 -> #REF! | E24: =D21+E21 -> #REF! | F24: =D21+E21+F21 -> #REF! | G24: =C21 -> 95964.675
A25: OBS: O PAGAMENTO SERÁ EXECUTADO APÓS A CONCLUSÃO DOS SERVIÇOS E ACEITO PELA FISCALIZAÇÃO INFRAERO.
